Workbook
Name AlertDays: Settings!$B$3
Name CBURegion: [1]Data!#REF!
Name Classification: [1]Data!#REF!
Name MonthCrit: Settings!$B$6
Name Owner: [1]Data!#REF!
Name PeriodSel: Settings!$B$8
Name Region: [1]Data!#REF!
Name ReportMonth: Settings!$B$4
Name ReportMonthName: Settings!$B$5
Name Sector: Settings!$B$2
Name SelGate: #REF!
Name SelMonth: #REF!
Name SelRegion: #REF!
Name SelYear: #REF!
Name Status: [1]Data!#REF!
Name Type: [1]Data!#REF!

Sheet Projects 
A1: بوابة 8 التسليم و الاغلاق | B1: بوابة 7 الاختبارات التشغيلية | C1: بوابة 6 التنفيذ | D1: بوابة 5 الطرح للتنفيذ | E1: بوابة 4 التصميم | F1: بوابة 3 الطرح للتصميم | G1: بوابة 2 التخطيط الاولي | H1: بوابة 1 تخطيط استراتيجي | I1: Simplified or Full SGR بسيطة او كاملة | J1: D&B vs DBB | K1: سبب المسار الجزئي | L1: مسار بوابة المراحل | M1: السبب للاستبعاد | N1: Updated SN | O1: اسم المشروع | P1: القطاع | Q1: المنطقة | R1: التكلفة شاملة الضريبة | S1: تصنيف حزم الطرح | T1: دراسة الجدوى | U1: مستندات الطرح | V1: حالة الطرح | W1: تفاصيل توقيع العقد والارتباط المالي | X1: وضع المشروع | Y1: تاريخ بوابة 6 المخطط | Z1: تاريخ بوابة 7 المخطط | AA1: تاريخ بوابة 8 المخطط
I2: =IF(R2>25000000,"Full","Simplified") -> Full | N2: AP51 | O2: عقد استكمال تنفيذ خطوط المياه والشبكات بمحافظة الافلاج (المرحلة الثانية) | P2: الأوسط | Q2: الرياض | R2: 57241417 | S2: الحزمة الأولى | T2: تم الإعتماد | U2: تم الإعتماد | V2: فحص العروض والترسية
I3: =IF(R3>25000000,"Full","Simplified") -> Full | J3: DBB | N3: AP48-8 | O3: عقد تنفيذ خزان او بحيرة تجميع لمياه الصرف الصحي الخام بمحطات معالجة الخرج بالقطاع الأوسط | P3: الأوسط | Q3: الرياض | R3: 32000000 | S3: الحزمة الأولى | T3: تم الإعتماد | U3: تم الإعتماد | V3: معتمد دراسة جدوى وRFP ولم يطرح (في انتظار موافقة كفاءة الانفاق)
I4: =IF(R4>25000000,"Full","Simplified") -> Simplified | N4: P1605-1 | O4: عقد تنفيذ شبكات مياه متفرقة بمحافظة الخرج منطقة الرياض | P4: الأوسط | Q4: الرياض | R4: 13436140 | S4: الحزمة الأولى | T4: تم الإعتماد | U4: تم الإعتماد | V4: منجز
I5: =IF(R5>25000000,"Full","Simplified") -> Full | N5: P1463-6 | O5: استبدال الخطوط الناقلة محافظة الدرعية وحريملاء | P5: الأوسط | Q5: الرياض | R5: 41067058 | S5: الحزمة الأولى | T5: تم الإعتماد | U5: تم الإعتماد | V5: تعزيز التكاليف
I6: =IF(R6>25000000,"Full","Simplified") -> Full | N6: P1744 | O6: برنامج تنفيذ محطة معالجة وخطوط وشبكات الصرف الصحي بمحافظة الدلم (المرحلة الأولى) | P6: الأوسط | Q6: الرياض | R6: 279450000 | S6: الحزمة الأولى | T6: تم الإعتماد | U6: تم الإعتماد | V6: معتمد دراسة جدوى وRFP ولم يطرح (في انتظار موافقة كفاءة الانفاق)
I7: =IF(R7>25000000,"Full","Simplified") -> Full | N7: AP40 | O7: عقد استكمال مشاريع المياه بمحافظة الدلم (المرحلة الأولى) | P7: الأوسط | Q7: الرياض | R7: 80500000 | S7: الحزمة الأولى | T7: تم الإعتماد | U7: تم الإعتماد | V7: التحليل الفني
I8: =IF(R8>25000000,"Full","Simplified") -> Full | N8: P1595-1 | O8: عقد تنفيذ عدد 2 محطة مياه مدمجة بسعة إجمالية 10,000م3/يوم بموقع اعمال محطة تنقية القرنة بمحافظة الدوادمي | P8: الأوسط | Q8: الرياض | R8: 25185000 | S8: الحزمة الأولى | T8: تم الإعتماد | U8: تم الإعتماد | V8: منجز
I9: =IF(R9>25000000,"Full","Simplified") -> Full | N9: AP1177 | O9: عقد تنفيذ توسعة محطة المعالجة بمحافظة الدوادمي المرحلة الثانية | P9: الأوسط | Q9: الرياض | R9: 75900000 | S9: الحزمة الأولى | T9: تم الإعتماد | U9: تم الإعتماد | V9: التحليل الفني
I10: =IF(R10>25000000,"Full","Simplified") -> Full | N10: P1813 | O10: عقد استكمال مشاريع المياه بمراكز نفي والجمش بمحافظة الدوادمي | P10: الأوسط | Q10: الرياض | R10: 119140000 | S10: الحزمة الأولى | T10: تم الإعتماد | U10: تم الإعتماد | V10: تعزيز التكاليف
I11: =IF(R11>25000000,"Full","Simplified") -> Full | N11: P1624 | O11: عقد تنفيذ خطوط صرف صحى رئيسية بشمال الرياض لأحياء العارض والقيروان - عقد رقم (4) | P11: الأوسط | Q11: الرياض | R11: 33805867 | S11: الحزمة الأولى | T11: تم الإعتماد | U11: تم الإعتماد | V11: منجز
I12: =IF(R12>25000000,"Full","Simplified") -> Full | N12: P1627 | O12: عقد تنفيذ شبكات صرف صحى بأجزاء من حى ظهرة لبن - عقد رقم (6) | P12: الأوسط | Q12: الرياض | R12: 30932102 | S12: الحزمة الأولى | T12: تم الإعتماد | U12: تم الإعتماد | V12: منجز
I13: =IF(R13>25000000,"Full","Simplified") -> Simplified | N13: P1632-2 | O13: عقد تنفيذ خطوط صرف صحى متفرقة بمدينة الرياض - عقد رقم (26) المرحلة الثانية | P13: الأوسط | Q13: الرياض | R13: 10215704 | S13: الحزمة الأولى | T13: تم الإعتماد | U13: تم الإعتماد | V13: منجز
I14: =IF(R14>25000000,"Full","Simplified") -> Full | N14: P1635 | O14: مشروع تنفيذ الخطوط الرئيسية ومحطة الرفع وشبكات الصرف الصحي بحي النرجس | P14: الأوسط | Q14: الرياض | R14: 4.5901941e+08 | S14: الحزمة الأولى | T14: تم الإعتماد | U14: تم الإعتماد | V14: منجز
I15: =IF(R15>25000000,"Full","Simplified") -> Full | N15: P1697 | O15: عقد تنفيذ المرحلة الثالثة من خط الصرف الصحي الرئيسي (LO) | P15: الأوسط | Q15: الرياض | R15: 45770144 | S15: الحزمة الأولى | T15: تم الإعتماد | U15: تم الإعتماد | V15: منجز
... I198: =IF(R198>25000000,"Full","Simplified") -> Full | N198: P563 | O198: مشروع انشاء شبكات مياه في محافظات وقرى منطقة حائل عقد رقم 5 | P198: الشمالي | Q198: حائل | R198: 66716360 | S198: الحزمة الأولى | T198: تم الإعتماد | U198: تم الإعتماد | V198: تعزيز التكاليف
D199: جاري | E199: مكتمل | F199: لا ينطبق | G199: مكتمل | H199: مكتمل | I199: =IF(R199>25000000,"Full","Simplified") -> Full | J199: DBB | K199: توجد اتفاقية أعمال التصميم مبرمة على مستوى القطاع (Cluster). لم يتم طرح لأعمال التصميم (No bid for design) | L199: صورة جزئية | N199: P858-1 | O199: تنفيذ شبكات الصرف الصحي في وسط الحناكية | P199: الشمالي الغربي | Q199: المدينة المنورة | R199: 88550000 | S199: الحزمة الأولى | T199: تم الإعتماد | U199: تم الإعتماد | V199: تعزيز التكاليف | AK199: مكتمل
D200: جاري | E200: مكتمل | F200: لا ينطبق | G200: مكتمل | H200: مكتمل | I200: =IF(R200>25000000,"Full","Simplified") -> Full | J200: DBB | K200: توجد اتفاقية أعمال التصميم مبرمة على مستوى القطاع (Cluster). لم يتم طرح لأعمال التصميم (No bid for design) | L200: صورة جزئية | N200: P856 | O200: تنفيذ خطوط وشبكات الصرف الصحي بمحافظة العلا ( الجزء الاول ) | P200: الشمالي الغربي | Q200: المدينة المنورة | R200: 1.5732436e+08 | S200: الحزمة الأولى | T200: تم الإعتماد | U200: تم الإعتماد | V200: تعزيز التكاليف | AK200: مكتمل بشروط
D201: جاري | E201: مكتمل | F201: لا ينطبق | G201: مكتمل | H201: مكتمل | I201: =IF(R201>25000000,"Full","Simplified") -> Full | J201: DBB | K201: توجد اتفاقية أعمال التصميم مبرمة على مستوى القطاع (Cluster). لم يتم طرح لأعمال التصميم (No bid for design) | L201: صورة جزئية | N201: P834 | O201: ترحيل خطوط وتنفيذ شبكات بمناطق متفرقة (المرحلة الثالثة) | P201: الشمالي الغربي | Q201: المدينة المنورة | R201: 1.1848035e+08 | S201: الحزمة الأولى | T201: تم الإعتماد | U201: تم الإعتماد | V201: تعزيز التكاليف | AK201: مرفوض
D202: جاري | E202: مكتمل | F202: لا ينطبق | G202: مكتمل | H202: مكتمل | I202: =IF(R202>25000000,"Full","Simplified") -> Full | J202: DBB | K202: توجد اتفاقية أعمال التصميم مبرمة على مستوى القطاع (Cluster). لم يتم طرح لأعمال التصميم (No bid for design) | L202: صورة جزئية | N202: P835 | O202: ترحيل خطوط وتنفيذ شبكات بمناطق متفرقة (المرحلة الرابعة) | P202: الشمالي الغربي | Q202: المدينة المنورة | R202: 132249724 | T202: تم الإعتماد | U202: تم الإعتماد | V202: تعزيز التكاليف | AK202: لا ينطبق
D203: جاري | E203: مكتمل | F203: لا ينطبق | G203: مكتمل | H203: مكتمل | I203: =IF(R203>25000000,"Full","Simplified") -> Full | J203: DBB | K203: توجد اتفاقية أعمال التصميم مبرمة على مستوى القطاع (Cluster). لم يتم طرح لأعمال التصميم (No bid for design) | L203: صورة جزئية | N203: P860 | O203: نقل ومعالجة الحماه من محطة معالجة مياه الصرف الصحي بالمدينة المنورة ( الجزء الأول ) | P203: الشمالي الغربي | Q203: المدينة المنورة | R203: 69000000 | S203: الحزمة الأولى | T203: تم الإعتماد | U203: تم الإعتماد | V203: إعادة طرح
D204: جاري | E204: مكتمل | F204: مكتمل | G204: مكتمل | H204: مكتمل | I204: =IF(R204>25000000,"Full","Simplified") -> Full | J204: DBB | L204: صورة كاملة | N204: P816-2 | O204: تنفيذ الخط الرئيسي للصرف الصحي وشبكات التجميع لخدمة توسعة المطار ومخطط العوينة والعاقول بالمدينة المنورة | P204: الشمالي الغربي | Q204: المدينة المنورة | R204: 2.4225834e+08 | S204: الحزمة الأولى | T204: تم الإعتماد | U204: تم الإعتماد | V204: تعزيز التكاليف
D205: جاري | E205: مكتمل | F205: مكتمل | G205: مكتمل | H205: مكتمل | I205: =IF(R205>25000000,"Full","Simplified") -> Full | J205: DBB | L205: صورة كاملة | N205: P848-2 | O205: تنفيذ خطوط وشبكات الصرف الصحي غرب المدينة المنورة | P205: الشمالي الغربي | Q205: المدينة المنورة | R205: 1.4561455e+08 | S205: الحزمة الأولى | T205: تم الإعتماد | U205: تم الإعتماد | V205: فحص العروض والترسية
D206: جاري | E206: مكتمل | F206: مكتمل | G206: مكتمل | H206: مكتمل | I206: =IF(R206>25000000,"Full","Simplified") -> Full | J206: DBB | L206: صورة كاملة | N206: P855 | O206: تنفيذ خطوط الرئيسية وشبكات الصرف الصحي شرق المدينة المنورة | P206: الشمالي الغربي | Q206: المدينة المنورة | R206: 2.8292677e+08 | S206: الحزمة الأولى | T206: تم الإعتماد | U206: تم الإعتماد | V206: تعزيز التكاليف
D207: جاري | E207: مكتمل | F207: مكتمل | G207: مكتمل | H207: مكتمل | I207: =IF(R207>25000000,"Full","Simplified") -> Full | J207: DBB | L207: صورة كاملة | N207: P863 | O207: تنفيذ خطوط وشبكات الصرف الصحي شمال المدينة المنورة | P207: الشمالي الغربي | Q207: المدينة المنورة | R207: 1.4694117e+08 | S207: الحزمة الأولى | T207: تم الإعتماد | U207: تم الإعتماد | V207: فحص العروض والترسية
D208: جاري | E208: مكتمل | F208: مكتمل | G208: مكتمل | H208: مكتمل | I208: =IF(R208>25000000,"Full","Simplified") -> Full | J208: DBB | L208: صورة كاملة | N208: P801 | O208: تنفيذ الخطوط الرئيسية والفرعية لايصال خدمة الصرف الصحي الى مستشفى التخصصي بحمراء الأسد | P208: الشمالي الغربي | Q208: المدينة المنورة | R208: 2.3554691e+08 | S208: الحزمة الأولى | T208: تم الإعتماد | U208: تم الإعتماد | V208: إعادة طرح
D209: جاري | E209: مكتمل | F209: لا ينطبق | G209: مكتمل | H209: مكتمل | I209: =IF(R209>25000000,"Full","Simplified") -> Full | J209: DBB | K209: توجد اتفاقية أعمال التصميم مبرمة على مستوى القطاع (Cluster). لم يتم طرح لأعمال التصميم (No bid for design) | L209: صورة جزئية | N209: P812 | O209: تنفيذ خط مياه الصرف الصحي من المنطقة المركزية الى محطة المعالجة بالمدينة المنورة (المرحلة الاولى) | P209: الشمالي الغربي | Q209: المدينة المنورة | R209: 130984747 | S209: الحزمة الأولى | T209: تم الإعتماد | U209: تم الإعتماد | V209: معتمد دراسة جدوى وRFP ولم يطرح (في انتظار موافقة كفاءة الانفاق)
E210: جاري | F210: لا ينطبق | G210: مكتمل | H210: مكتمل | I210: =IF(R210>25000000,"Full","Simplified") -> Full | J210: DBB | K210: توجد اتفاقية أعمال التصميم مبرمة على مستوى القطاع (Cluster). لم يتم طرح لأعمال التصميم (No bid for design) | L210: صورة جزئية | N210: AP1228 | O210: تنفيذ خطوط وشبكات المياه بمخططات العوينة بالمدينة المنورة | P210: الشمالي الغربي | Q210: المدينة المنورة | R210: 60000000 | S210: الحزمة الأولى | T210: لدى القطاع لتعديل الملاحظات | U210: أعمال حقلية 10% | V210: لم يتم إستلام طلب الشراء
E211: جاري | F211: لا ينطبق | G211: مكتمل | H211: مكتمل | I211: =IF(R211>25000000,"Full","Simplified") -> Full | J211: DBB | K211: توجد اتفاقية أعمال التصميم مبرمة على مستوى القطاع (Cluster). لم يتم طرح لأعمال التصميم (No bid for design) | L211: صورة جزئية | N211: P846-3 | O211: تنفيذ شبكات الصرف الصحي بمخططات الرانوناء واحياء جنوب المدينة ( المرحلة الثانية) | P211: الشمالي الغربي | Q211: المدينة المنورة | R211: 97750000 | S211: الحزمة الأولى | T211: لدى القطاع لتعديل الملاحظات | U211: أعمال حقلية 10% | V211: لم يتم إستلام طلب الشراء
E212: جاري | F212: لا ينطبق | G212: مكتمل | H212: مكتمل | I212: =IF(R212>25000000,"Full","Simplified") -> Full | J212: DBB | K212: توجد اتفاقية أعمال التصميم مبرمة على مستوى القطاع (Cluster). لم يتم طرح لأعمال التصميم (No bid for design) | L212: صورة جزئية | N212: P846-5 | O212: تنفيذ شبكات الصرف الصحي بمخططات شوران واحياء جنوب المدينة | P212: الشمالي الغربي | Q212: المدينة المنورة | R212: 85000000 | S212: الحزمة الأولى | T212: لدى القطاع لتعديل الملاحظات | U212: أعمال حقلية 10% | V212: لم يتم إستلام طلب الشراء
D213: جاري | E213: مكتمل | F213: مكتمل | G213: مكتمل | H213: مكتمل | I213: =IF(R213>25000000,"Full","Simplified") -> Full | J213: DBB | L213: صورة كاملة | N213: P917-2 | O213: تنقيذ شبكات وخطوط مياه قرى المدينة المنورة ( الجزء الثاني) | P213: الشمالي الغربي | Q213: المدينة المنورة | R213: 55680638 | S213: الحزمة الأولى | T213: تم الإعتماد | U213: تم الإعتماد | V213: تعزيز التكاليف
I214: =IF(R214>25000000,"Full","Simplified") -> Full | M214: المشروع منجز | N214: P896-1 | O214: تنفيذ خط خروج خزانات غرب المدينة | P214: الشمالي الغربي | Q214: المدينة المنورة | R214: 29301148 | S214: الحزمة الأولى | T214: تم الإعتماد | U214: تم الإعتماد | V214: منجز
D215: جاري | E215: مكتمل | F215: مكتمل | G215: مكتمل | H215: مكتمل | I215: =IF(R215>25000000,"Full","Simplified") -> Simplified | J215: DBB | L215: صورة كاملة | N215: AP241 | O215: مشروع انشاء اشياب محطات تعبئة الصهاريج الناقلة للمياه بمنطقة المدينة المنورة | P215: الشمالي الغربي | Q215: المدينة المنورة | R215: 10746806 | S215: الحزمة الأولى | T215: تم الإعتماد | U215: تم الإعتماد | V215: تعزيز التكاليف
D216: جاري | E216: مكتمل | F216: مكتمل | G216: مكتمل | H216: مكتمل | I216: =IF(R216>25000000,"Full","Simplified") -> Full | J216: DBB | L216: صورة كاملة | N216: P907 | O216: تنفيذ خطوط وشبكات مياه منطقة غرب المدينة المنورة | P216: الشمالي الغربي | Q216: المدينة المنورة | R216: 118754739 | S216: الحزمة الأولى | T216: تم الإعتماد | U216: تم الإعتماد | V216: تعزيز التكاليف
E217: جاري | F217: لا ينطبق | G217: مكتمل | H217: مكتمل | I217: =IF(R217>25000000,"Full","Simplified") -> Full | J217: DBB | K217: توجد اتفاقية أعمال التصميم مبرمة على مستوى القطاع (Cluster). لم يتم طرح لأعمال التصميم (No bid for design) | L217: صورة جزئية | N217: PP218 | O217: تنفيذ شبكات المياه لمخططات المنح (الهضبة - الياسمين - الشروق) | P217: الشمالي الغربي | Q217: المدينة المنورة | R217: 162401120 | S217: الحزمة الأولى | T217: لدى القطاع لتعديل الملاحظات | U217: أعمال حقلية 10% | V217: لم يتم إستلام طلب الشراء
D218: جاري | E218: مكتمل | F218: مكتمل | G218: مكتمل | H218: مكتمل | I218: =IF(R218>25000000,"Full","Simplified") -> Full | J218: DBB | K218: توجد اتفاقية أعمال التصميم مبرمة على مستوى القطاع (Cluster). لم يتم طرح لأعمال التصميم (No bid for design) | L218: صورة جزئية | N218: AP270 | O218: تنفيذ خطوط وشبكات توزيع المياه بمحافظة المهد | P218: الشمالي الغربي | Q218: المدينة المنورة | R218: 1.7233344e+08 | S218: الحزمة الأولى | T218: تم الإعتماد | U218: تم الإعتماد | V218: إعادة طرح
D219: جاري | E219: مكتمل | F219: مكتمل | G219: مكتمل | H219: مكتمل | I219: =IF(R219>25000000,"Full","Simplified") -> Full | J219: DBB | L219: صورة كاملة | N219: P906 | O219: تنفيذ شبكات وخطوط مياه للسويرقية والعقيلية | P219: الشمالي الغربي | Q219: المدينة المنورة | R219: 1.1675848e+08 | S219: الحزمة الأولى | T219: تم الإعتماد | U219: تم الإعتماد | V219: فحص العروض والترسية
D220: جاري | E220: مكتمل | F220: لا ينطبق | G220: مكتمل | H220: مكتمل | I220: =IF(R220>25000000,"Full","Simplified") -> Full | J220: DBB | K220: توجد اتفاقية أعمال التصميم مبرمة على مستوى القطاع (Cluster). لم يتم طرح لأعمال التصميم (No bid for design) | L220: صورة جزئية | N220: P914 | O220: تنفيد الخطوط الرئيسية والفرعية والخزانات بالجفر | P220: الشمالي الغربي | Q220: المدينة المنورة | R220: 56525881 | S220: الحزمة الأولى | T220: تم الإعتماد | U220: تم الإعتماد | V220: تعزيز التكاليف
D221: مشروع خطوط فرعية وتوصيلات منزلية للصرف الصحي مع اعادة تاهيل محطة الضخ بينبع. | E221: مكتمل | F221: لا ينطبق | G221: مكتمل | H221: مكتمل | I221: =IF(R221>25000000,"Full","Simplified") -> Full | J221: DBB | K221: توجد اتفاقية أعمال التصميم مبرمة على مستوى القطاع (Cluster). لم يتم طرح لأعمال التصميم (No bid for design) | L221: صورة جزئية | N221: P859 | O221: تنفيذ خطوط وشبكات الصرف الصحي بمحافظة خيبر( الجزء الأول ) | P221: الشمالي الغربي | Q221: المدينة المنورة | R221: 82587652 | S221: الحزمة الأولى | T221: تم الإعتماد | U221: تم الإعتماد | V221: تعزيز التكاليف
D222: جاري | E222: مكتمل | F222: لا ينطبق | G222: مكتمل | H222: مكتمل | I222: =IF(R222>25000000,"Full","Simplified") -> Full | J222: DBB | K222: توجد اتفاقية أعمال التصميم مبرمة على مستوى القطاع (Cluster). لم يتم طرح لأعمال التصميم (No bid for design) | L222: صورة جزئية | N222: P919 | O222: تنفيذ شبكات وخطوط المياه بمحافظة خيبر | P222: الشمالي الغربي | Q222: المدينة المنورة | R222: 64047340 | S222: الحزمة الأولى | T222: تم الإعتماد | U222: تم الإعتماد | V222: تعزيز التكاليف
...

Sheet LIVE PMO
A1: PMO | B1: Project Number | C1: رقم العقد التشغيلي | D1: إسم المشروع | E1: الجهة المسئولة | F1: تاريخ نهاية العقد المعدل | G1: الاستلام الابتدائي الفعلي | H1: الاستلام النهائي الفعلي | I1: وضع المشروع | J1: تاريخ توقيع محضر الاستلام الابتدائي | K1: المنطقة | L1: إجمالي القيمة (مليون)
A2: Yes | B2: 1142 | C2: 03/17/2/01/0012/1 | D2: استكمال تنفيذ الخطوط الرئيسية وشبكات المياه بالمدينة المنورة | E2: منطقة المدينة المنورة | F2: 45120 | G2: 45985 | I2: استلام ابتدائي | J2: 46036 | K2: المدينة المنورة | L2: 59.55
A3: Yes | B3: 10081 | C3: 08/23/2/11/0001/1 | D3: مشروع استكمال شبكات المياه وأعمال الربط للخطوط الرئيسية وأعمال مواقع المياه بمدينة تبوك | E3: منطقة تبوك | F3: 46188 | G3: 46135 | I3: استلام ابتدائي | J3: 46161 | K3: تبوك | L3: 44.01
A4: Yes | B4: 10101 | C4: 03/23/2/01/0003/2 | D4: تنفيذ شبكات وخطوط مياه بالعوينة والعاقول بالمدينة المنورة | E4: منطقة المدينة المنورة | F4: 46706 | I4: منتظم | K4: المدينة المنورة | L4: 56.75
A5: Yes | B5: 10128 | C5: 03/23/2/02/0007/1 | D5: تنفيذ شبكات الصرف الصحى بمحافظات منطقه المدينه المنورة الخطوط الرئيسيه | E5: منطقة المدينة المنورة | F5: 46311 | I5: منتظم | K5: المدينة المنورة | L5: 44.27
A6: Yes | B6: 10129 | C6: 03/23/2/02/0004/1 | D6: مشروع تنفيذ شبكات الصرف الصحي باحياء الجرف بالمدينة المنورة | E6: منطقة المدينة المنورة | F6: 46730 | I6: منتظم | K6: المدينة المنورة | L6: 78.22
A7: Yes | B7: 10136 | C7: 03/23/2/02/0005/1 | D7: تنفيذ خطوط فرعية وتوصيلات منزلية للصرف الصحي مع اعادة تأهيل محطة الضخ بينبع | E7: منطقة المدينة المنورة | F7: 46430 | I7: متأخر | K7: المدينة المنورة | L7: 48.38
A8: Yes | B8: 10137 | C8: 03/23/2/02/0010/1 | D8: تنفيذ شبكات الصرف الصحي بمخططات الرانوناء واحياء جنوب المدينة ( المرحلة الأولى ) | E8: منطقة المدينة المنورة | F8: 46379 | I8: متأخر | K8: المدينة المنورة | L8: 37.84
A9: Consultancy | B9: AP1039-9 | C9: 03/23/1/02/0012/1 | D9: اتفاقية الخدمات الهندسية والاستشارية لتقديم خدمات الإشراف على تنفيذ مشاريع المياه والصرف الصحي بالقطاع الشمالي الغربي عقد (1) | E9: منطقة المدينة المنورة | F9: 46985 | I9: استشاري | K9: المدينة المنورة | L9: 98.67
A10: Consultancy | B10: AP1038-9 | C10: 03/23/1/03/0017/1 | D10: اتفاقية الخدمات الهندسية الاستشارية لإعداد الدراسات والتصاميم لمشاريع المياه والصرف الصحي بالقطاع الشمالي الغربي عقد (1) | E10: منطقة المدينة المنورة | F10: 46407 | I10: استشاري | K10: المدينة المنورة | L10: 122.82
A11: Yes | B11: 10203 | C11: 03/23/2/02/0011/1 | D11: تنفيذ خطوط الصرف الصحي الرئيسية بمخططات الرانوناء واحياء جنوب المدينة | E11: منطقة المدينة المنورة | F11: 46741 | I11: متقدم | K11: المدينة المنورة | L11: 117.21
A12: Yes | B12: 10204 | C12: 03/23/2/01/0016/1 | D12: إحلال شبكات وخطوط مياه بمدينة ينبع | E12: منطقة المدينة المنورة | F12: 46379 | I12: متعثر | K12: المدينة المنورة | L12: 26.81
A13: Consultancy | B13: AP1038-10 | C13: 03/23/1/03/0015/1 | D13: الخدمات الهندسيةالاستشارية الدراسات والتصاميم والهندسة القيمية لمشاريع المياه والصرف الصحي بالقطاع الشمالي الغربي رقم2 | E13: منطقة المدينة المنورة | F13: 46408 | I13: استشاري | K13: المدينة المنورة | L13: 221.14
A14: Consultancy | B14: P877-1 | C14: 03/23/1/09/0018/1 | D14: اعمال الرفع المساحي لاراضي واصول المياه والصرف الصحي المستقبلية بمنطقة المدينة المنورة | E14: منطقة المدينة المنورة | F14: 46415 | I14: استشاري | K14: المدينة المنورة | L14: 0.82
A15: Yes | B15: P898-1 | C15: 03/23/2/01/0023/1 | D15: مشروع إستكمال تنفيذ الخطوط الرئيسية والشبكات الفرعية لمخططات شوران ( المرحلة الأولى ) | E15: منطقة المدينة المنورة | F15: 47014 | I15: متقدم | K15: المدينة المنورة | L15: 111.77
... A18: Yes | B18: P878 | C18: 03/23/2/01/0028/1 | D18: احلال شبكات و خطوط مياه - المدينة المنورة | E18: منطقة المدينة المنورة | F18: 46936 | I18: متقدم | K18: المدينة المنورة | L18: 24.83
A19: Yes | B19: O1005 | C19: 03/23/2/08/0025/1 | D19: استكمال إنشاء خزان مياه تجميعي 10,000م3 ببيضان محافظة المهد | E19: منطقة المدينة المنورة | F19: 46037 | G19: 46023 | I19: استلام ابتدائي | J19: 46026 | K19: المدينة المنورة | L19: 8.6
A20: Yes | B20: P894-1 | C20: 03/23/2/11/0019/1 | D20: مشروع تنفيذ خط المياه الرئيسي في الدائري الثالث شرق المدينة المنورة | E20: منطقة المدينة المنورة | F20: 46581 | I20: متقدم | K20: المدينة المنورة | L20: 26.15
A21: Yes | B21: P848-1 | C21: 03/23/2/12/0027/1 | D21: تنفيذ خط الصرف الصحي الرئيسي بالدعيثة | E21: منطقة المدينة المنورة | F21: 46079 | G21: 45973 | I21: استلام ابتدائي | J21: 46030 | K21: المدينة المنورة | L21: 20.94
A22: Yes | B22: O1021 | C22: 08/23/2/01/0003/1 | D22: استكمال مشروع انشاء شبكات مياه الشرب بقرية المعظم بتبوك | E22: منطقة تبوك | F22: 46034 | G22: 46033 | I22: استلام ابتدائي | J22: 46090 | K22: تبوك | L22: 9.3
A23: Yes | B23: 10256 | C23: 08/23/2/03/0006/1 | D23: تنفيذ الاعمال لإنشاء محطة تنقية مياه الشرب بنظام الحاوية المدمجة للقليبة بمنطقة تبوك سعة 1000 م3\يوم | E23: منطقة تبوك | F23: 47058 | I23: متقدم | K23: تبوك | L23: 39.5
A24: Yes | B24: O192 | C24: 03/23/2/01/0030/1 | D24: استكمال تنفيذ خطوط وشبكات المياه بأحياء شرق المدينة المنورة والعاقول | E24: منطقة المدينة المنورة | F24: 46480 | I24: متعثر | K24: المدينة المنورة | L24: 44.88
A25: Yes | B25: O1006 | C25: 03/23/2/13/0033/1 | D25: توريد وتركيب وحدات معالجة الحمأة ميكانيكيا بالمدينة المنورة | E25: منطقة المدينة المنورة | F25: 46269 | I25: متأخر | K25: المدينة المنورة | L25: 18.57
A26: Yes | B26: O1014 | C26: 08/23/2/04/0007/1 | D26: استكمال مشروع توسعة محطة المعالجة بأملج إلى المرحلة الثلاثية | E26: منطقة تبوك | F26: 46082 | G26: 46082 | I26: استلام ابتدائي | J26: 46142 | K26: تبوك | L26: 42.71
A27: Yes | B27: P852 | C27: 3/25/2/2/P852/1 | D27: مشروع استكمال شبكات الصرف الصحى لحى البرماوية | E27: منطقة المدينة المنورة | F27: 46841 | I27: متقدم | K27: المدينة المنورة | L27: 14.1
A28: Yes | B28: AP243 | C28: 3/25/2/1/AP243/1 | D28: تنفيذ خطوط وشبكات توزيع المياه لمحافظة العيص ( المرحلة الأولى ) | E28: منطقة المدينة المنورة | F28: 46857 | I28: متقدم | K28: المدينة المنورة | L28: 58.22
A29: Yes | B29: P829 | C29: 3/24/2/1/P829/1 | D29: تنفيذ خط المياه الرئيسي لتغذية توسعة المطار | E29: منطقة المدينة المنورة | F29: 46201 | I29: مسحوب | K29: المدينة المنورة | L29: 20.81
A30: Yes | B30: AP251 | C30: 3/25/2/2/AP251/1 | D30: تنفيذ مشاريع إيصال خدمات الصرف الصحي لمخططات الإسكان بالمدينة المنورة ( 4 مواقع ) | E30: منطقة المدينة المنورة | F30: 47309 | I30: متقدم | K30: المدينة المنورة | L30: 72.45
A31: Yes | B31: AP244 | C31: 8/25/2/2/AP244/1 | D31: انشاء مصبات الصهاريج بمحطات معالجة الصرف الصحي بمنطقة تبوك | E31: منطقة تبوك | F31: 46820 | I31: منتظم | K31: تبوك | L31: 18.2
A32: Yes | B32: P825 | C32: 3/25/2/1/P825/1 | D32: خط المياه الرئيسي بالدائري الأوسط بالمدينة المنورة | E32: منطقة المدينة المنورة | F32: 47302 | I32: متقدم | K32: المدينة المنورة | L32: 116.76
A33: Yes | B33: P861 | C33: 3/25/2/2/P861/1 | D33: تنفيذ خطوط وشبكات الصرف الصحي مخطط جبل عير | E33: منطقة المدينة المنورة | F33: 47252 | I33: متقدم | K33: المدينة المنورة | L33: 82.86
A34: Yes | B34: P918 | C34: 3/25/2/1/P918/1 | D34: مشروع إنشاء خط مياه رئيسي من المسيجيد الى هبت مع محطة ضخ في المسيجيد ومحطة أخرى في بئر الروحاء | E34: منطقة المدينة المنورة | F34: 47239 | I34: متقدم | K34: المدينة المنورة | L34: 43.41
A35: Yes | B35: 10277 | C35: 03/23/2/02/0032/1 | D35: إستكمال تنفيذ شبكات الصرف الصحي بالأماكن المتضررة بالمدينة المنورة | E35: منطقة المدينة المنورة | F35: 46232 | I35: متأخر | K35: المدينة المنورة | L35: 26.02
A36: Yes | B36: 10296 | C36: 08/23/2/01/0009/1 | D36: مشروع إنشاء شبكات مياه الشرب لحي الرايس بمدينة تبوك | E36: منطقة تبوك | F36: 46810 | I36: متقدم | K36: تبوك | L36: 12.47
A37: Yes | B37: 10278 | C37: 03/23/2/02/0031/1 | D37: مشروع انشاء شبكات وخطوط الصرف الصحي بحي الأصيفرين بالمدينة المنورة | E37: منطقة المدينة المنورة | F37: 47004 | I37: منتظم | K37: المدينة المنورة | L37: 63.67
A38: Yes | B38: 10279 | C38: 03/23/2/02/0035/1 | D38: تنفيذ شبكات الصرف الصحي بمحافظة ينبع | E38: منطقة المدينة المنورة | F38: 46368 | I38: منتظم | K38: المدينة المنورة | L38: 22.68
... A40: Yes | B40: 10281 | C40: 03/23/2/02/0034/1 | D40: استكمال مشروع شبكات الصرف الصحي والتوصيلات المنزلية بينبع | E40: منطقة المدينة المنورة | F40: 46322 | I40: متعثر | K40: المدينة المنورة | L40: 25.75
A41: Yes | B41: P1498 | C41: 08/23/2/01/0010/1 | D41: شبكات المياه باحياء النظيم وجنوب تبوك | E41: منطقة تبوك | F41: 46287 | G41: 46141 | I41: استلام ابتدائي | J41: 46166 | K41: تبوك | L41: 5.72
A42: Yes | B42: AP257 | C42: 8/25/2/2/AP257/1 | D42: تنفيذ نظام لنقل مياه الصرف الصحي لمنفذ الدرة بحقل | E42: منطقة تبوك | F42: 46959 | I42: منتظم | K42: تبوك | L42: 13.77
A43: Yes | B43: AP247 | C43: 03/23/2/01/0045/1 | D43: تنفيذ خطوط وشبكات توزيع المياه بمحافظة بدر | E43: منطقة المدينة المنورة | F43: 47217 | I43: متقدم | K43: المدينة المنورة | L43: 29.65
...

Sheet NWC Colors
A1: اللون | B1: HEX | C1: الاستخدام | D1: عينة
A2: Navy (أساسي) | B2: #0A2F5C | C2: العناوين والهيدر
A3: Blue | B3: #0072BC | C3: السلاسل الرئيسية
A4: Mid Blue | B4: #005EA8 | C4: سلاسل ثانوية
A5: Cyan | B5: #00A3E0 | C5: تمييز / Accent
A6: Teal | B6: #00B2A9 | C6: المكتمل
A7: Dark Grey | B7: #40566B | C7: نص
A8: Grey | B8: #7A8B99 | C8: نص ثانوي / غير منطبق
A9: Light Grey | B9: #D5DDE5 | C9: حدود / لاحقة
A10: Canvas | B10: #F2F5F8 | C10: خلفية اللوحة
A11: Red (حالة) | B11: #D13438 | C11: متأخر
A12: Amber (حالة) | B12: #FFB900 | C12: خلال أسبوعين
A13: Green (حالة) | B13: #107C10 | C13: في الموعد

Sheet Dashboard Calc
A1: حسابات لوحة المتابعة — مربوطة بجدول GateFacts (مصدره Projects (2)) وتتأثر بالفلاتر | R1: قائمة مستحقات الشهر الحالي (كل البوابات التي تاريخها داخل الشهر) | Y1: مشاريع البوابة المختارة في الفلتر (غير مكتملة) مرتبة حسب البوابة ثم الأيام المتبقية | AI1: حسابات شيت Dashboard (مربوطة بجدول GateFacts / Projects (2))
A2: المؤشر | B2: القيمة | D2: رقم | E2: البوابة | F2: مكتملة | G2: الحالية (جارية) | H2: لاحقة | I2: لا ينطبق | J2: قيمة المشاريع الحالية (مليون ريال) | L2: حالة التنبيه | M2: العدد | O2: حالة الطرح | P2: العدد | R2: Updated SN | S2: اسم المشروع | T2: المنطقة | U2: البوابة | V2: التاريخ | W2: الأيام المتبقية | Y2: Updated SN | Z2: اسم المشروع | AA2: المنطقة | AB2: البوابة الحالية | AC2: تاريخ البوابة | AD2: الأيام المتبقية | AE2: حالة التنبيه | AF2: التكلفة | AI2: القطاع | AJ2: الشمالي الغربي
A3: عدد المشاريع | B3: =COUNTIFS(GateFacts[رقم البوابة],1,GateFacts[ظاهر],1) -> 0 | D3: 1 | E3: =INDEX(GateFacts[البوابة],MATCH(D3,GateFacts[رقم البوابة],0))&" - "&INDEX(GateFacts[اسم البوابة],MATCH(D3,GateFacts[رقم البوابة],0)) -> بوابة 1 - تخطيط استراتيجي | F3: =COUNTIFS(GateFacts[رقم البوابة],D3,GateFacts[ظاهر],1,GateFacts[الحالة],"مكتمل") -> 0 | G3: =COUNTIFS(GateFacts[IsCurrentGate],1,GateFacts[ظاهر],1,GateFacts[رقم البوابة],D3) -> 0 | H3: =$B$3-F3-G3-I3 -> 0 | I3: =COUNTIFS(GateFacts[رقم البوابة],D3,GateFacts[ظاهر],1,GateFacts[الحالة],"لا ينطبق") -> 0 | J3: =SUMIFS(GateFacts[التكلفة],GateFacts[IsCurrentGate],1,GateFacts[ظاهر],1,GateFacts[رقم البوابة],D3)/1000000 -> 0 | L3: =A6 -> متأخر / مستحق اليوم | M3: =B6 -> 0 | O3: {=_xlfn.LET(_xlpm.s,_xlfn._xlws.FILTER(GateFacts[حالة الطرح],(GateFacts[رقم البوابة]=1)*(GateFacts[ظاهر]=1)*(GateFacts[حالة الطرح]<>""),""),_xlpm.u,_xlfn.UNIQUE(_xlpm.s),_xlpm.c,_xlfn.MAP(_xlpm.u,_xlfn.LAMBDA(_xlpm.x,SUM(--(_xlpm.s=_xlpm.x)))),_xlpm.t,_xlfn.TAKE(_xlfn.SORTBY(_xlfn.HSTACK(_xlpm.u,_xlpm.c),_xlpm.c,-1),8),_xlfn.EXPAND(_xlpm.t,8,2,""))} -> #REF! | R3: {=_xlfn.LET(_xlpm.ok,(ISNUMBER(GateFacts[تاريخ البوابة]))*(GateFacts[تاريخ البوابة]>=$B$12)*(GateFacts[تاريخ البوابة]<=$B$13)*(GateFacts[ظاهر]=1),IF(SUM(_xlpm.ok)=0,"لا توجد مستحقات هذا الشهر",_xlfn.SORTBY(_xlfn._xlws.FILTER(_xlfn.HSTACK(GateFacts[SN],GateFacts[اسم المشروع],GateFacts[المنطقة],GateFacts[البوابة],GateFacts[تاريخ البوابة],GateFacts[الأيام المتبقية]),_xlpm.ok),_xlfn._xlws.FILTER(GateFacts[تاريخ البوابة],_xlpm.ok),1)))} -> #REF! | Y3: {=_xlfn.LET(_xlpm.ok,(GateFacts[IsCurrentGate]=1)*(GateFacts[ظاهر]=1)*(GateFacts[البوابة الحالية للمشروع]<9),IF(SUM(_xlpm.ok)=0,"لا توجد مشاريع",_xlfn.SORTBY(_xlfn._xlws.FILTER(_xlfn.HSTACK(GateFacts[SN],GateFacts[اسم المشروع],GateFacts[المنطقة],GateFacts[البوابة],GateFacts[تاريخ البوابة],GateFacts[الأيام المتبقية],GateFacts[الحالة],GateFacts[التكلفة]),_xlpm.ok),_xlfn._xlws.FILTER(GateFacts[رقم البوابة],_xlpm.ok),1)))} -> #REF! | AL3: رقم | AM3: البوابة | AN3: جاري (البوابة الحالية) | AO3: مقبول / ناجح | AP3: مقبول بشروط | AR3: حالة العقد | AS3: عدد | AU3: حالة العقد (مرتبة) | AV3: عدد
A4: إجمالي القيمة (ريال) | B4: =SUMIFS(GateFacts[التكلفة],GateFacts[رقم البوابة],1,GateFacts[ظاهر],1) -> 0 | D4: 2 | E4: =INDEX(GateFacts[البوابة],MATCH(D4,GateFacts[رقم البوابة],0))&" - "&INDEX(GateFacts[اسم البوابة],MATCH(D4,GateFacts[رقم البوابة],0)) -> بوابة 2 - التخطيط الاولي | F4: =COUNTIFS(GateFacts[رقم البوابة],D4,GateFacts[ظاهر],1,GateFacts[الحالة],"مكتمل") -> 0 | G4: =COUNTIFS(GateFacts[IsCurrentGate],1,GateFacts[ظاهر],1,GateFacts[رقم البوابة],D4) -> 0 | H4: =$B$3-F4-G4-I4 -> 0 | I4: =COUNTIFS(GateFacts[رقم البوابة],D4,GateFacts[ظاهر],1,GateFacts[الحالة],"لا ينطبق") -> 0 | J4: =SUMIFS(GateFacts[التكلفة],GateFacts[IsCurrentGate],1,GateFacts[ظاهر],1,GateFacts[رقم البوابة],D4)/1000000 -> 0 | L4: =A7 -> خلال أسبوعين | M4: =B7 -> 0 | AI4: عدد المشاريع | AJ4: =COUNTIFS(Table15[القطاع],$AJ$2) -> 130 | AL4: 1 | AM4: {=SUBSTITUTE(INDEX(Table15[#Headers],9-AL4),CHAR(10)," - ")} -> بوابة 1 - تخطيط استراتيجي | AN4: =COUNTIFS(GateFacts[IsCurrentGate],1,GateFacts[ظاهر],1,GateFacts[القطاع],$AJ$2,GateFacts[رقم البوابة],AL4) -> 0 | AO4: {=SUMPRODUCT((Table15[القطاع]=$AJ$2)*(INDEX(Table15[],0,9-AL4)="مكتمل"))} -> 103 | AP4: {=SUMPRODUCT((Table15[القطاع]=$AJ$2)*(INDEX(Table15[],0,9-AL4)="مكتمل بشروط"))} -> 0 | AR4: غير محدد | AU4: {=_xlfn.SORTBY(AR4:AS14,AS4:AS14,-1)} -> غير محدد | AV4: 0
A5: مكتملة كل البوابات | B5: =COUNTIFS(GateFacts[رقم البوابة],1,GateFacts[ظاهر],1,GateFacts[البوابة الحالية للمشروع],9) -> 0 | D5: 3 | E5: =INDEX(GateFacts[البوابة],MATCH(D5,GateFacts[رقم البوابة],0))&" - "&INDEX(GateFacts[اسم البوابة],MATCH(D5,GateFacts[رقم البوابة],0)) -> بوابة 3 - الطرح للتصميم | F5: =COUNTIFS(GateFacts[رقم البوابة],D5,GateFacts[ظاهر],1,GateFacts[الحالة],"مكتمل") -> 0 | G5: =COUNTIFS(GateFacts[IsCurrentGate],1,GateFacts[ظاهر],1,GateFacts[رقم البوابة],D5) -> 0 | H5: =$B$3-F5-G5-I5 -> 0 | I5: =COUNTIFS(GateFacts[رقم البوابة],D5,GateFacts[ظاهر],1,GateFacts[الحالة],"لا ينطبق") -> 0 | J5: =SUMIFS(GateFacts[التكلفة],GateFacts[IsCurrentGate],1,GateFacts[ظاهر],1,GateFacts[رقم البوابة],D5)/1000000 -> 0 | L5: =A8 -> جاري | M5: =B8 -> 0 | AI5: إجمالي القيمة (ريال) | AJ5: =SUMIFS(Table15[التكلفة شاملة الضريبة],Table15[القطاع],$AJ$2) -> 8.2530192e+09 | AL5: 2 | AM5: {=SUBSTITUTE(INDEX(Table15[#Headers],9-AL5),CHAR(10)," - ")} -> بوابة 2 - التخطيط الاولي | AN5: =COUNTIFS(GateFacts[IsCurrentGate],1,GateFacts[ظاهر],1,GateFacts[القطاع],$AJ$2,GateFacts[رقم البوابة],AL5) -> 0 | AO5: {=SUMPRODUCT((Table15[القطاع]=$AJ$2)*(INDEX(Table15[],0,9-AL5)="مكتمل"))} -> 103 | AP5: {=SUMPRODUCT((Table15[القطاع]=$AJ$2)*(INDEX(Table15[],0,9-AL5)="مكتمل بشروط"))} -> 0 | AR5: متقدم | AU5: متقدم | AV5: 0
A6: متأخر / مستحق اليوم | B6: =COUNTIFS(GateFacts[IsCurrentGate],1,GateFacts[ظاهر],1,GateFacts[الحالة],Settings!$Q$3) -> 0 | D6: 4 | E6: =INDEX(GateFacts[البوابة],MATCH(D6,GateFacts[رقم البوابة],0))&" - "&INDEX(GateFacts[اسم البوابة],MATCH(D6,GateFacts[رقم البوابة],0)) -> بوابة 4 - التصميم | F6: =COUNTIFS(GateFacts[رقم البوابة],D6,GateFacts[ظاهر],1,GateFacts[الحالة],"مكتمل") -> 0 | G6: =COUNTIFS(GateFacts[IsCurrentGate],1,GateFacts[ظاهر],1,GateFacts[رقم البوابة],D6) -> 0 | H6: =$B$3-F6-G6-I6 -> 0 | I6: =COUNTIFS(GateFacts[رقم البوابة],D6,GateFacts[ظاهر],1,GateFacts[الحالة],"لا ينطبق") -> 0 | J6: =SUMIFS(GateFacts[التكلفة],GateFacts[IsCurrentGate],1,GateFacts[ظاهر],1,GateFacts[رقم البوابة],D6)/1000000 -> 0 | L6: =A9 -> بدون حالة | M6: =B9 -> 0 | AI6: الجارية في البوابات | AJ6: =AJ7+AJ8 -> 120 | AL6: 3 | AM6: {=SUBSTITUTE(INDEX(Table15[#Headers],9-AL6),CHAR(10)," - ")} -> بوابة 3 - الطرح للتصميم | AN6: =COUNTIFS(GateFacts[IsCurrentGate],1,GateFacts[ظاهر],1,GateFacts[القطاع],$AJ$2,GateFacts[رقم البوابة],AL6) -> 0 | AO6: {=SUMPRODUCT((Table15[القطاع]=$AJ$2)*(INDEX(Table15[],0,9-AL6)="مكتمل"))} -> 28 | AP6: {=SUMPRODUCT((Table15[القطاع]=$AJ$2)*(INDEX(Table15[],0,9-AL6)="مكتمل بشروط"))} -> 0 | AR6: منتظم | AU6: منتظم | AV6: 0
A7: خلال أسبوعين | B7: =COUNTIFS(GateFacts[IsCurrentGate],1,GateFacts[ظاهر],1,GateFacts[الحالة],Settings!$Q$4) -> 0 | D7: 5 | E7: =INDEX(GateFacts[البوابة],MATCH(D7,GateFacts[رقم البوابة],0))&" - "&INDEX(GateFacts[اسم البوابة],MATCH(D7,GateFacts[رقم البوابة],0)) -> بوابة 5 - الطرح للتنفيذ | F7: =COUNTIFS(GateFacts[رقم البوابة],D7,GateFacts[ظاهر],1,GateFacts[الحالة],"مكتمل") -> 0 | G7: =COUNTIFS(GateFacts[IsCurrentGate],1,GateFacts[ظاهر],1,GateFacts[رقم البوابة],D7) -> 0 | H7: =$B$3-F7-G7-I7 -> 0 | I7: =COUNTIFS(GateFacts[رقم البوابة],D7,GateFacts[ظاهر],1,GateFacts[الحالة],"لا ينطبق") -> 0 | J7: =SUMIFS(GateFacts[التكلفة],GateFacts[IsCurrentGate],1,GateFacts[ظاهر],1,GateFacts[رقم البوابة],D7)/1000000 -> 0 | AI7: مسار جزئي | AJ7: =COUNTIFS(Table15[القطاع],$AJ$2,Table15[مسار بوابة المراحل],"*جزئي*") -> 92 | AL7: 4 | AM7: {=SUBSTITUTE(INDEX(Table15[#Headers],9-AL7),CHAR(10)," - ")} -> بوابة 4 - التصميم | AN7: =COUNTIFS(GateFacts[IsCurrentGate],1,GateFacts[ظاهر],1,GateFacts[القطاع],$AJ$2,GateFacts[رقم البوابة],AL7) -> 0 | AO7: {=SUMPRODUCT((Table15[القطاع]=$AJ$2)*(INDEX(Table15[],0,9-AL7)="مكتمل"))} -> 95 | AP7: {=SUMPRODUCT((Table15[القطاع]=$AJ$2)*(INDEX(Table15[],0,9-AL7)="مكتمل بشروط"))} -> 0 | AR7: استلام ابتدائي | AU7: استلام ابتدائي | AV7: 0
A8: جاري | B8: =COUNTIFS(GateFacts[IsCurrentGate],1,GateFacts[ظاهر],1,GateFacts[الحالة],"جاري") -> 0 | D8: 6 | E8: =INDEX(GateFacts[البوابة],MATCH(D8,GateFacts[رقم البوابة],0))&" - "&INDEX(GateFacts[اسم البوابة],MATCH(D8,GateFacts[رقم البوابة],0)) -> بوابة 6 - التنفيذ | F8: =COUNTIFS(GateFacts[رقم البوابة],D8,GateFacts[ظاهر],1,GateFacts[الحالة],"مكتمل") -> 0 | G8: =COUNTIFS(GateFacts[IsCurrentGate],1,GateFacts[ظاهر],1,GateFacts[رقم البوابة],D8) -> 0 | H8: =$B$3-F8-G8-I8 -> 0 | I8: =COUNTIFS(GateFacts[رقم البوابة],D8,GateFacts[ظاهر],1,GateFacts[الحالة],"لا ينطبق") -> 0 | J8: =SUMIFS(GateFacts[التكلفة],GateFacts[IsCurrentGate],1,GateFacts[ظاهر],1,GateFacts[رقم البوابة],D8)/1000000 -> 0 | AI8: مسار كامل | AJ8: =COUNTIFS(Table15[القطاع],$AJ$2,Table15[مسار بوابة المراحل],"*كامل*") -> 28 | AL8: 5 | AM8: {=SUBSTITUTE(INDEX(Table15[#Headers],9-AL8),CHAR(10)," - ")} -> بوابة 5 - الطرح للتنفيذ | AN8: =COUNTIFS(GateFacts[IsCurrentGate],1,GateFacts[ظاهر],1,GateFacts[القطاع],$AJ$2,GateFacts[رقم البوابة],AL8) -> 0 | AO8: {=SUMPRODUCT((Table15[القطاع]=$AJ$2)*(INDEX(Table15[],0,9-AL8)="مكتمل"))} -> 77 | AP8: {=SUMPRODUCT((Table15[القطاع]=$AJ$2)*(INDEX(Table15[],0,9-AL8)="مكتمل بشروط"))} -> 0 | AR8: استشاري | AU8: استشاري | AV8: 0
A9: بدون حالة | B9: =B3-B5-B6-B7-B8 -> 0 | D9: 7 | E9: =INDEX(GateFacts[البوابة],MATCH(D9,GateFacts[رقم البوابة],0))&" - "&INDEX(GateFacts[اسم البوابة],MATCH(D9,GateFacts[رقم البوابة],0)) -> بوابة 7 - الاختبارات التشغيلية | F9: =COUNTIFS(GateFacts[رقم البوابة],D9,GateFacts[ظاهر],1,GateFacts[الحالة],"مكتمل") -> 0 | G9: =COUNTIFS(GateFacts[IsCurrentGate],1,GateFacts[ظاهر],1,GateFacts[رقم البوابة],D9) -> 0 | H9: =$B$3-F9-G9-I9 -> 0 | I9: =COUNTIFS(GateFacts[رقم البوابة],D9,GateFacts[ظاهر],1,GateFacts[الحالة],"لا ينطبق") -> 0 | J9: =SUMIFS(GateFacts[التكلفة],GateFacts[IsCurrentGate],1,GateFacts[ظاهر],1,GateFacts[رقم البوابة],D9)/1000000 -> 0 | AI9: المستبعدة من بوابة المراحل | AJ9: =COUNTIFS(Table15[القطاع],$AJ$2,Table15[السبب للاستبعاد],"<>") -> 10 | AL9: 6 | AM9: {=SUBSTITUTE(INDEX(Table15[#Headers],9-AL9),CHAR(10)," - ")} -> بوابة 6 - التنفيذ | AN9: =COUNTIFS(GateFacts[IsCurrentGate],1,GateFacts[ظاهر],1,GateFacts[القطاع],$AJ$2,GateFacts[رقم البوابة],AL9) -> 0 | AO9: {=SUMPRODUCT((Table15[القطاع]=$AJ$2)*(INDEX(Table15[],0,9-AL9)="مكتمل"))} -> 10 | AP9: {=SUMPRODUCT((Table15[القطاع]=$AJ$2)*(INDEX(Table15[],0,9-AL9)="مكتمل بشروط"))} -> 0 | AR9: متأخر | AU9: متأخر | AV9: 0
A10: مستحقات هذا الشهر (بوابات) | B10: =COUNTIFS(GateFacts[ظاهر],1,GateFacts[تاريخ البوابة],">="&B12,GateFacts[تاريخ البوابة],"<="&B13) -> 0 | D10: 8 | E10: =INDEX(GateFacts[البوابة],MATCH(D10,GateFacts[رقم البوابة],0))&" - "&INDEX(GateFacts[اسم البوابة],MATCH(D10,GateFacts[رقم البوابة],0)) -> بوابة 8 - التسليم و الاغلاق | F10: =COUNTIFS(GateFacts[رقم البوابة],D10,GateFacts[ظاهر],1,GateFacts[الحالة],"مكتمل") -> 0 | G10: =COUNTIFS(GateFacts[IsCurrentGate],1,GateFacts[ظاهر],1,GateFacts[رقم البوابة],D10) -> 0 | H10: =$B$3-F10-G10-I10 -> 0 | I10: =COUNTIFS(GateFacts[رقم البوابة],D10,GateFacts[ظاهر],1,GateFacts[الحالة],"لا ينطبق") -> 0 | J10: =SUMIFS(GateFacts[التكلفة],GateFacts[IsCurrentGate],1,GateFacts[ظاهر],1,GateFacts[رقم البوابة],D10)/1000000 -> 0 | AI10: DBB | AJ10: =COUNTIFS(Table15[القطاع],$AJ$2,Table15[D&B vs DBB],"DBB") -> 117 | AL10: 7 | AM10: {=SUBSTITUTE(INDEX(Table15[#Headers],9-AL10),CHAR(10)," - ")} -> بوابة 7 - الاختبارات التشغيلية | AN10: =COUNTIFS(GateFacts[IsCurrentGate],1,GateFacts[ظاهر],1,GateFacts[القطاع],$AJ$2,GateFacts[رقم البوابة],AL10) -> 0 | AO10: {=SUMPRODUCT((Table15[القطاع]=$AJ$2)*(INDEX(Table15[],0,9-AL10)="مكتمل"))} -> 10 | AP10: {=SUMPRODUCT((Table15[القطاع]=$AJ$2)*(INDEX(Table15[],0,9-AL10)="مكتمل بشروط"))} -> 0 | AR10: مسحوب | AU10: مسحوب | AV10: 0
A11: اليوم | B11: =TODAY() -> 46309 | AI11: D&B | AJ11: =COUNTIFS(Table15[القطاع],$AJ$2,Table15[D&B vs DBB],"D&B") -> 3 | AL11: 8 | AM11: {=SUBSTITUTE(INDEX(Table15[#Headers],9-AL11),CHAR(10)," - ")} -> بوابة 8 - التسليم و الاغلاق | AN11: =COUNTIFS(GateFacts[IsCurrentGate],1,GateFacts[ظاهر],1,GateFacts[القطاع],$AJ$2,GateFacts[رقم البوابة],AL11) -> 0 | AO11: {=SUMPRODUCT((Table15[القطاع]=$AJ$2)*(INDEX(Table15[],0,9-AL11)="مكتمل"))} -> 0 | AP11: {=SUMPRODUCT((Table15[القطاع]=$AJ$2)*(INDEX(Table15[],0,9-AL11)="مكتمل بشروط"))} -> 0 | AR11: متعثر | AU11: متعثر | AV11: 0
A12: بداية الشهر | B12: =EOMONTH(B11,-1)+1 -> 46296 | AI12: مستبعد: المشروع منجز | AJ12: =COUNTIFS(Table15[القطاع],$AJ$2,Table15[السبب للاستبعاد],"المشروع منجز") -> 4 | AR12: ايقاف كلي | AU12: ايقاف كلي | AV12: 0
A13: نهاية الشهر | B13: =EOMONTH(B11,0) -> 46326 | AI13: مستبعد: عقد استشاري | AJ13: =COUNTIFS(Table15[القطاع],$AJ$2,Table15[السبب للاستبعاد],"عقد استشاري") -> 6 | AR13: مسحوب (مهلة) | AU13: مسحوب (مهلة) | AV13: 0
A14: اسم الشهر | B14: =CHOOSE(MONTH(B11),"يناير","فبراير","مارس","أبريل","مايو","يونيو","يوليو","أغسطس","سبتمبر","أكتوبر","نوفمبر","ديسمبر")&" "&YEAR(B11) -> أكتوبر 2026 | AI14: % مسار جزئي | AJ14: =IFERROR(AJ7/AJ4,0) -> 0.70769231 | AR14: مكتمل التنفيذ | AU14: مكتمل التنفيذ | AV14: 0
A15: القطاع (ثابت) | B15: الشمالي الغربي | AI15: % مسار كامل | AJ15: =IFERROR(AJ8/AJ4,0) -> 0.21538462
A16: حد التنبيه (أيام) | B16: 14 | AI16: البوابة المختارة في الفلتر | AJ16: {=IFERROR(_xlfn.TEXTJOIN("، ",,_xlfn.UNIQUE(_xlfn._xlws.FILTER(GateFacts[البوابة],(GateFacts[IsCurrentGate]=1)*(GateFacts[القطاع]=$AJ$2)))),"-")} -> بوابة 5، بوابة 4، بوابة 1، بوابة 6، بوابة 8

Sheet Settings
A1: الإعداد | B1: القيمة | D1: رقم البوابة | E1: اسم البوابة | F1: عمود المصدر في Table1 | H1: صفوف القطاع في Table1 | I1: عدد المشاريع | J1: صفوف GateFacts المطلوبة | L1: Calendar - التاريخ | M1: السنة | N1: الشهر | O1: السنة-الشهر | Q1: الحالة | R1: اللون | S1: ملاحظة | U1: قائمة الأشهر (للفلتر) | V1: قائمة البوابات (للفلتر) | W1: قائمة المناطق (للفلتر) | X1: قائمة السنوات (للفلتر) | Y1: أشهر السنة المختارة (للفلتر)
A2: القطاع | B2: الشمالي الغربي | D2: 1 | E2: تخطيط استراتيجي | F2: H | H2: {=_xlfn._xlws.FILTER(_xlfn.SEQUENCE(ROWS(Table15[])),TRIM(Table15[القطاع])=Sector,"")} -> 198 | I2: =COUNT(_xlfn.ANCHORARRAY(H2)) -> 130 | J2: =I2*8 -> 1040 | L2: {=_xlfn.LET(_xlpm.g,INDEX(Table15[],0,1):INDEX(Table15[],0,8),_xlpm.d,IF(ISNUMBER(_xlpm.g),_xlpm.g,""),_xlpm.a,DATE(YEAR(MIN(TODAY(),MIN(_xlpm.d))),1,1),_xlpm.b,DATE(YEAR(MAX(TODAY(),MAX(_xlpm.d))),12,31),_xlfn.SEQUENCE(_xlpm.b-_xlpm.a+1,1,_xlpm.a))} -> 1 | M2: {=YEAR(_xlfn.ANCHORARRAY(L2))} -> 1900 | N2: {=MONTH(_xlfn.ANCHORARRAY(L2))} -> 1 | O2: {=TEXT(_xlfn.ANCHORARRAY(L2),"yyyy-mm")} -> 1900-01 | Q2: مكتمل | R2: #00B2A9 | S2: مكتمل / مكتمل بشروط | U2: {=_xlfn.VSTACK("الكل",_xlfn._xlws.SORT(_xlfn.UNIQUE(_xlfn._xlws.FILTER(GateFacts[شهر البوابة],GateFacts[شهر البوابة]<>"بدون تاريخ"))))} -> الكل | V2: {=_xlfn.VSTACK("الكل","بوابة "&_xlfn.SEQUENCE(8))} -> الكل | W2: {=_xlfn.VSTACK("الكل",_xlfn._xlws.SORT(_xlfn.UNIQUE(_xlfn._xlws.FILTER(GateFacts[المنطقة],GateFacts[المنطقة]<>""))))} -> الكل | X2: {=_xlfn.VSTACK("الكل",--_xlfn.UNIQUE(LEFT(_xlfn.DROP(_xlfn.ANCHORARRAY(U2),1),4)))} -> الكل | Y2: {=_xlfn.LET(_xlpm.m,_xlfn.DROP(_xlfn.ANCHORARRAY(U2),1),_xlpm.y,SelYear&"",_xlfn.VSTACK("الكل",IF(_xlpm.y="الكل",_xlpm.m,_xlfn._xlws.FILTER(_xlpm.m,LEFT(_xlpm.m,4)=_xlpm.y,"لا توجد أشهر"))))} -> #REF!
A3: أيام التنبيه | B3: 14 | D3: 2 | E3: التخطيط الاولي | F3: G | H3: 199 | L3: 2 | M3: 1900 | N3: 1 | O3: 1900-01 | Q3: متأخر | R3: #C0392B | S3: وصل موعدها اليوم أو تجاوزته وغير مكتملة | U3: 2023-07 | V3: بوابة 1 | W3: المدينة المنورة | X3: 2023
A4: شهر الملخص (من فلتر اللوحة) | B4: =IF(LEN(PeriodSel)<>7,DATE(YEAR(TODAY()),MONTH(TODAY()),1),DATEVALUE(PeriodSel&"-01")) -> #REF! | D4: 3 | E4: الطرح للتصميم | F4: F | H4: 200 | L4: 3 | M4: 1900 | N4: 1 | O4: 1900-01 | Q4: خلال أسبوعين | R4: #F4B400 | S4: خلال 14 يوماً قبل الموعد | U4: 2026-01 | V4: بوابة 2 | W4: تبوك | X4: 2026
A5: اسم الشهر | B5: =IF(AND(PeriodSel<>"الكل",LEN(PeriodSel)=4),"سنة "&PeriodSel,CHOOSE(MONTH(B4),"يناير","فبراير","مارس","أبريل","مايو","يونيو","يوليو","أغسطس","سبتمبر","أكتوبر","نوفمبر","ديسمبر")&" "&YEAR(B4)) -> #REF! | D5: 4 | E5: التصميم | F5: E | H5: 201 | L5: 4 | M5: 1900 | N5: 1 | O5: 1900-01 | Q5: في الموعد | R5: #0072BC | S5: بعد فترة التنبيه | U5: 2026-02 | V5: بوابة 3 | X5: 2027
A6: معيار الشهر | B6: =IF(PeriodSel="الكل","*",PeriodSel&"*") -> #REF! | D6: 5 | E6: الطرح للتنفيذ | F6: D | H6: 202 | L6: 5 | M6: 1900 | N6: 1 | O6: 1900-01 | Q6: بدون تاريخ | R6: #D5DDE5 | S6: جاري أو فارغة وغير مكتملة | U6: 2026-03 | V6: بوابة 4 | X6: 2028
A7: السنة المختارة | B7: {=SelYear&""} -> #REF! | D7: 6 | E7: التنفيذ | F7: C | H7: 203 | L7: 6 | M7: 1900 | N7: 1 | O7: 1900-01 | Q7: لا ينطبق | R7: #7A8B99 | S7: مستبعد من النسب | U7: 2026-04 | V7: بوابة 5 | X7: 2029
A8: الفترة الفعلية (سنة/شهر) | B8: =IF(AND(SelMonth&""<>"الكل",OR(B7="الكل",LEFT(SelMonth&"",4)=B7)),SelMonth&"",B7) -> #REF! | D8: 7 | E8: الاختبارات التشغيلية | F8: B | H8: 204 | L8: 7 | M8: 1900 | N8: 1 | O8: 1900-01 | U8: 2026-05 | V8: بوابة 6 | X8: 2030
D9: 8 | E9: التسليم و الاغلاق | F9: A | H9: 205 | L9: 8 | M9: 1900 | N9: 1 | O9: 1900-01 | U9: 2026-06 | V9: بوابة 7 | X9: 2031
H10: 206 | L10: 9 | M10: 1900 | N10: 1 | O10: 1900-01 | U10: 2026-07 | V10: بوابة 8
H11: 207 | L11: 10 | M11: 1900 | N11: 1 | O11: 1900-01 | U11: 2026-08
H12: 208 | L12: 11 | M12: 1900 | N12: 1 | O12: 1900-01 | U12: 2026-09
H13: 209 | L13: 12 | M13: 1900 | N13: 1 | O13: 1900-01 | U13: 2026-10
H14: 210 | L14: 13 | M14: 1900 | N14: 1 | O14: 1900-01 | U14: 2026-12
H15: 211 | L15: 14 | M15: 1900 | N15: 1 | O15: 1900-01 | U15: 2027-01
H16: 212 | L16: 15 | M16: 1900 | N16: 1 | O16: 1900-01 | U16: 2027-02
H17: 213 | L17: 16 | M17: 1900 | N17: 1 | O17: 1900-01 | U17: 2027-03
H18: 214 | L18: 17 | M18: 1900 | N18: 1 | O18: 1900-01 | U18: 2027-04
H19: 215 | L19: 18 | M19: 1900 | N19: 1 | O19: 1900-01 | U19: 2027-05
H20: 216 | L20: 19 | M20: 1900 | N20: 1 | O20: 1900-01 | U20: 2027-07
H21: 217 | L21: 20 | M21: 1900 | N21: 1 | O21: 1900-01 | U21: 2027-08
H22: 218 | L22: 21 | M22: 1900 | N22: 1 | O22: 1900-01 | U22: 2027-09
... H63: 586 | L63: 62 | M63: 1900 | N63: 3 | O63: 1900-03 | U63: 2031-07
H64: 599 | L64: 63 | M64: 1900 | N64: 3 | O64: 1900-03
H65: 609 | L65: 64 | M65: 1900 | N65: 3 | O65: 1900-03
H66: 612 | L66: 65 | M66: 1900 | N66: 3 | O66: 1900-03
H67: 614 | L67: 66 | M67: 1900 | N67: 3 | O67: 1900-03
H68: 615 | L68: 67 | M68: 1900 | N68: 3 | O68: 1900-03
H69: 620 | L69: 68 | M69: 1900 | N69: 3 | O69: 1900-03
H70: 632 | L70: 69 | M70: 1900 | N70: 3 | O70: 1900-03
H71: 633 | L71: 70 | M71: 1900 | N71: 3 | O71: 1900-03
H72: 650 | L72: 71 | M72: 1900 | N72: 3 | O72: 1900-03
H73: 654 | L73: 72 | M73: 1900 | N73: 3 | O73: 1900-03
H74: 655 | L74: 73 | M74: 1900 | N74: 3 | O74: 1900-03
H75: 657 | L75: 74 | M75: 1900 | N75: 3 | O75: 1900-03
... H131: 1058 | L131: 130 | M131: 1900 | N131: 5 | O131: 1900-05
L132: 131 | M132: 1900 | N132: 5 | O132: 1900-05
L133: 132 | M133: 1900 | N133: 5 | O133: 1900-05
L134: 133 | M134: 1900 | N134: 5 | O134: 1900-05
L135: 134 | M135: 1900 | N135: 5 | O135: 1900-05
...

Sheet GateFacts
A1: م | B1: رقم المشروع | C1: رقم البوابة | D1: صف المصدر | E1: SN | F1: اسم المشروع | G1: المنطقة | H1: التكلفة | I1: حالة الطرح | J1: البوابة | K1: اسم البوابة | L1: القيمة الأصلية | M1: القيمة الموحدة | N1: تاريخ البوابة | O1: الحالة | P1: الأيام المتبقية | Q1: شهر البوابة | R1: منجزة | S1: البوابة الحالية للمشروع | T1: IsCurrentGate | U1: خلل التسلسل | V1: ظاهر | W1: القطاع
A2: {=ROW()-ROW(GateFacts[#Headers])} -> 1 | B2: =INT((GateFacts[[#This Row],[م]]-1)/8)+1 -> 1 | C2: =MOD(GateFacts[[#This Row],[م]]-1,8)+1 -> 1 | D2: {=IFERROR(INDEX(_xlfn.ANCHORARRAY(Settings!$H$2),GateFacts[[#This Row],[رقم المشروع]]),"")} -> 198 | E2: {=INDEX(Table15[],GateFacts[[#This Row],[صف المصدر]],14)&""} -> P858-1 | F2: {=INDEX(Table15[],GateFacts[[#This Row],[صف المصدر]],15)&""} -> تنفيذ شبكات الصرف الصحي في وسط الحناكية | G2: {=INDEX(Table15[],GateFacts[[#This Row],[صف المصدر]],17)&""} -> المدينة المنورة | H2: =N(INDEX(Table15[],GateFacts[[#This Row],[صف المصدر]],18)) -> 88550000 | I2: {=_xlfn.LET(_xlpm.x,TRIM(INDEX(Table15[],GateFacts[[#This Row],[صف المصدر]],22)&""),IF(_xlpm.x="","غير محدد",_xlpm.x))} -> تعزيز التكاليف | J2: ="بوابة "&GateFacts[[#This Row],[رقم البوابة]] -> بوابة 1 | K2: {=INDEX(Settings!$E$2:$E$9,GateFacts[[#This Row],[رقم البوابة]])} -> تخطيط استراتيجي | L2: {=_xlfn.LET(_xlpm.c,INDEX(Table15[],GateFacts[[#This Row],[صف المصدر]],9-GateFacts[[#This Row],[رقم البوابة]]),IF(ISBLANK(_xlpm.c),"",_xlpm.c))} -> مكتمل | M2: =_xlfn.LET(_xlpm.v,GateFacts[[#This Row],[القيمة الأصلية]],_xlpm.x,TRIM(_xlpm.v&""),IF(ISNUMBER(_xlpm.v),"تاريخ",IF(OR(_xlpm.x="N/A",_xlpm.x="NA",_xlpm.x="لا ينطبق"),"لا ينطبق",IF(OR(_xlpm.x="مكتمل",_xlpm.x="مكتمل بشروط",_xlpm.x="جاري"),_xlpm.x,IF(_xlpm.x="","فارغ","غير معروف"))))) -> مكتمل | N2: {=_xlfn.LET(_xlpm.r,GateFacts[[#This Row],[صف المصدر]],_xlpm.g,GateFacts[[#This Row],[رقم البوابة]],_xlpm.pd,IF(AND(ISNUMBER(_xlpm.r),_xlpm.g>=6,_xlpm.g<=8),INDEX(Table15[],_xlpm.r,19+_xlpm.g),""),IF(ISNUMBER(_xlpm.pd),_xlpm.pd,""))} | O2: =_xlfn.LET(_xlpm.m,GateFacts[[#This Row],[القيمة الموحدة]],_xlpm.d,GateFacts[[#This Row],[تاريخ البوابة]],IF(OR(_xlpm.m="مكتمل",_xlpm.m="مكتمل بشروط"),Settings!$Q$2,IF(_xlpm.m="لا ينطبق",Settings!$Q$7,IF(AND(ISNUMBER(_xlpm.d),_xlpm.d<=TODAY()),Settings!$Q$3,IF(AND(ISNUMBER(_xlpm.d),_xlpm.d<=TODAY()+AlertDays),Settings!$Q$4,IF(_xlpm.m="جاري","جاري","")))))) -> مكتمل | P2: =IF(ISNUMBER(GateFacts[[#This Row],[تاريخ البوابة]]),GateFacts[[#This Row],[تاريخ البوابة]]-TODAY(),"") | Q2: =IF(ISNUMBER(GateFacts[[#This Row],[تاريخ البوابة]]),TEXT(GateFacts[[#This Row],[تاريخ البوابة]],"yyyy-mm"),"بدون تاريخ") -> بدون تاريخ | R2: =--OR(GateFacts[[#This Row],[الحالة]]="مكتمل",GateFacts[[#This Row],[الحالة]]="لا ينطبق") -> 1 | S2: =_xlfn.LET(_xlpm.m,_xlfn.MINIFS(GateFacts[رقم البوابة],GateFacts[رقم المشروع],GateFacts[[#This Row],[رقم المشروع]],GateFacts[منجزة],0),IF(_xlpm.m=0,9,_xlpm.m)) -> 5 | T2: =--(GateFacts[[#This Row],[رقم البوابة]]=GateFacts[[#This Row],[البوابة الحالية للمشروع]]) -> 0 | U2: =IF(AND(GateFacts[[#This Row],[الحالة]]="مكتمل",COUNTIFS(GateFacts[رقم المشروع],GateFacts[[#This Row],[رقم المشروع]],GateFacts[رقم البوابة],"<"&GateFacts[[#This Row],[رقم البوابة]],GateFacts[منجزة],0)>0),1,0) -> 0 | V2: =SUBTOTAL(103,GateFacts[[#This Row],[م]])*OR(SelRegion="الكل",GateFacts[[#This Row],[المنطقة]]=SelRegion) -> #REF! | W2: {=IF(ISNUMBER(GateFacts[[#This Row],[صف المصدر]]),INDEX(Table15[],GateFacts[[#This Row],[صف المصدر]],16),"")} -> الشمالي الغربي
A3: {=ROW()-ROW(GateFacts[#Headers])} -> 2 | B3: =INT((GateFacts[[#This Row],[م]]-1)/8)+1 -> 1 | C3: =MOD(GateFacts[[#This Row],[م]]-1,8)+1 -> 2 | D3: {=IFERROR(INDEX(_xlfn.ANCHORARRAY(Settings!$H$2),GateFacts[[#This Row],[رقم المشروع]]),"")} -> 198 | E3: {=INDEX(Table15[],GateFacts[[#This Row],[صف المصدر]],14)&""} -> P858-1 | F3: {=INDEX(Table15[],GateFacts[[#This Row],[صف المصدر]],15)&""} -> تنفيذ شبكات الصرف الصحي في وسط الحناكية | G3: {=INDEX(Table15[],GateFacts[[#This Row],[صف المصدر]],17)&""} -> المدينة المنورة | H3: =N(INDEX(Table15[],GateFacts[[#This Row],[صف المصدر]],18)) -> 88550000 | I3: {=_xlfn.LET(_xlpm.x,TRIM(INDEX(Table15[],GateFacts[[#This Row],[صف المصدر]],22)&""),IF(_xlpm.x="","غير محدد",_xlpm.x))} -> تعزيز التكاليف | J3: ="بوابة "&GateFacts[[#This Row],[رقم البوابة]] -> بوابة 2 | K3: {=INDEX(Settings!$E$2:$E$9,GateFacts[[#This Row],[رقم البوابة]])} -> التخطيط الاولي | L3: {=_xlfn.LET(_xlpm.c,INDEX(Table15[],GateFacts[[#This Row],[صف المصدر]],9-GateFacts[[#This Row],[رقم البوابة]]),IF(ISBLANK(_xlpm.c),"",_xlpm.c))} -> مكتمل | M3: =_xlfn.LET(_xlpm.v,GateFacts[[#This Row],[القيمة الأصلية]],_xlpm.x,TRIM(_xlpm.v&""),IF(ISNUMBER(_xlpm.v),"تاريخ",IF(OR(_xlpm.x="N/A",_xlpm.x="NA",_xlpm.x="لا ينطبق"),"لا ينطبق",IF(OR(_xlpm.x="مكتمل",_xlpm.x="مكتمل بشروط",_xlpm.x="جاري"),_xlpm.x,IF(_xlpm.x="","فارغ","غير معروف"))))) -> مكتمل | N3: {=_xlfn.LET(_xlpm.r,GateFacts[[#This Row],[صف المصدر]],_xlpm.g,GateFacts[[#This Row],[رقم البوابة]],_xlpm.pd,IF(AND(ISNUMBER(_xlpm.r),_xlpm.g>=6,_xlpm.g<=8),INDEX(Table15[],_xlpm.r,19+_xlpm.g),""),IF(ISNUMBER(_xlpm.pd),_xlpm.pd,""))} | O3: =_xlfn.LET(_xlpm.m,GateFacts[[#This Row],[القيمة الموحدة]],_xlpm.d,GateFacts[[#This Row],[تاريخ البوابة]],IF(OR(_xlpm.m="مكتمل",_xlpm.m="مكتمل بشروط"),Settings!$Q$2,IF(_xlpm.m="لا ينطبق",Settings!$Q$7,IF(AND(ISNUMBER(_xlpm.d),_xlpm.d<=TODAY()),Settings!$Q$3,IF(AND(ISNUMBER(_xlpm.d),_xlpm.d<=TODAY()+AlertDays),Settings!$Q$4,IF(_xlpm.m="جاري","جاري","")))))) -> مكتمل | P3: =IF(ISNUMBER(GateFacts[[#This Row],[تاريخ البوابة]]),GateFacts[[#This Row],[تاريخ البوابة]]-TODAY(),"") | Q3: =IF(ISNUMBER(GateFacts[[#This Row],[تاريخ البوابة]]),TEXT(GateFacts[[#This Row],[تاريخ البوابة]],"yyyy-mm"),"بدون تاريخ") -> بدون تاريخ | R3: =--OR(GateFacts[[#This Row],[الحالة]]="مكتمل",GateFacts[[#This Row],[الحالة]]="لا ينطبق") -> 1 | S3: =_xlfn.LET(_xlpm.m,_xlfn.MINIFS(GateFacts[رقم البوابة],GateFacts[رقم المشروع],GateFacts[[#This Row],[رقم المشروع]],GateFacts[منجزة],0),IF(_xlpm.m=0,9,_xlpm.m)) -> 5 | T3: =--(GateFacts[[#This Row],[رقم البوابة]]=GateFacts[[#This Row],[البوابة الحالية للمشروع]]) -> 0 | U3: =IF(AND(GateFacts[[#This Row],[الحالة]]="مكتمل",COUNTIFS(GateFacts[رقم المشروع],GateFacts[[#This Row],[رقم المشروع]],GateFacts[رقم البوابة],"<"&GateFacts[[#This Row],[رقم البوابة]],GateFacts[منجزة],0)>0),1,0) -> 0 | V3: =SUBTOTAL(103,GateFacts[[#This Row],[م]])*OR(SelRegion="الكل",GateFacts[[#This Row],[المنطقة]]=SelRegion) -> #REF! | W3: {=IF(ISNUMBER(GateFacts[[#This Row],[صف المصدر]]),INDEX(Table15[],GateFacts[[#This Row],[صف المصدر]],16),"")} -> الشمالي الغربي
A4: {=ROW()-ROW(GateFacts[#Headers])} -> 3 | B4: =INT((GateFacts[[#This Row],[م]]-1)/8)+1 -> 1 | C4: =MOD(GateFacts[[#This Row],[م]]-1,8)+1 -> 3 | D4: {=IFERROR(INDEX(_xlfn.ANCHORARRAY(Settings!$H$2),GateFacts[[#This Row],[رقم المشروع]]),"")} -> 198 | E4: {=INDEX(Table15[],GateFacts[[#This Row],[صف المصدر]],14)&""} -> P858-1 | F4: {=INDEX(Table15[],GateFacts[[#This Row],[صف المصدر]],15)&""} -> تنفيذ شبكات الصرف الصحي في وسط الحناكية | G4: {=INDEX(Table15[],GateFacts[[#This Row],[صف المصدر]],17)&""} -> المدينة المنورة | H4: =N(INDEX(Table15[],GateFacts[[#This Row],[صف المصدر]],18)) -> 88550000 | I4: {=_xlfn.LET(_xlpm.x,TRIM(INDEX(Table15[],GateFacts[[#This Row],[صف المصدر]],22)&""),IF(_xlpm.x="","غير محدد",_xlpm.x))} -> تعزيز التكاليف | J4: ="بوابة "&GateFacts[[#This Row],[رقم البوابة]] -> بوابة 3 | K4: {=INDEX(Settings!$E$2:$E$9,GateFacts[[#This Row],[رقم البوابة]])} -> الطرح للتصميم | L4: {=_xlfn.LET(_xlpm.c,INDEX(Table15[],GateFacts[[#This Row],[صف المصدر]],9-GateFacts[[#This Row],[رقم البوابة]]),IF(ISBLANK(_xlpm.c),"",_xlpm.c))} -> لا ينطبق | M4: =_xlfn.LET(_xlpm.v,GateFacts[[#This Row],[القيمة الأصلية]],_xlpm.x,TRIM(_xlpm.v&""),IF(ISNUMBER(_xlpm.v),"تاريخ",IF(OR(_xlpm.x="N/A",_xlpm.x="NA",_xlpm.x="لا ينطبق"),"لا ينطبق",IF(OR(_xlpm.x="مكتمل",_xlpm.x="مكتمل بشروط",_xlpm.x="جاري"),_xlpm.x,IF(_xlpm.x="","فارغ","غير معروف"))))) -> لا ينطبق | N4: {=_xlfn.LET(_xlpm.r,GateFacts[[#This Row],[صف المصدر]],_xlpm.g,GateFacts[[#This Row],[رقم البوابة]],_xlpm.pd,IF(AND(ISNUMBER(_xlpm.r),_xlpm.g>=6,_xlpm.g<=8),INDEX(Table15[],_xlpm.r,19+_xlpm.g),""),IF(ISNUMBER(_xlpm.pd),_xlpm.pd,""))} | O4: =_xlfn.LET(_xlpm.m,GateFacts[[#This Row],[القيمة الموحدة]],_xlpm.d,GateFacts[[#This Row],[تاريخ البوابة]],IF(OR(_xlpm.m="مكتمل",_xlpm.m="مكتمل بشروط"),Settings!$Q$2,IF(_xlpm.m="لا ينطبق",Settings!$Q$7,IF(AND(ISNUMBER(_xlpm.d),_xlpm.d<=TODAY()),Settings!$Q$3,IF(AND(ISNUMBER(_xlpm.d),_xlpm.d<=TODAY()+AlertDays),Settings!$Q$4,IF(_xlpm.m="جاري","جاري","")))))) -> لا ينطبق | P4: =IF(ISNUMBER(GateFacts[[#This Row],[تاريخ البوابة]]),GateFacts[[#This Row],[تاريخ البوابة]]-TODAY(),"") | Q4: =IF(ISNUMBER(GateFacts[[#This Row],[تاريخ البوابة]]),TEXT(GateFacts[[#This Row],[تاريخ البوابة]],"yyyy-mm"),"بدون تاريخ") -> بدون تاريخ | R4: =--OR(GateFacts[[#This Row],[الحالة]]="مكتمل",GateFacts[[#This Row],[الحالة]]="لا ينطبق") -> 1 | S4: =_xlfn.LET(_xlpm.m,_xlfn.MINIFS(GateFacts[رقم البوابة],GateFacts[رقم المشروع],GateFacts[[#This Row],[رقم المشروع]],GateFacts[منجزة],0),IF(_xlpm.m=0,9,_xlpm.m)) -> 5 | T4: =--(GateFacts[[#This Row],[رقم البوابة]]=GateFacts[[#This Row],[البوابة الحالية للمشروع]]) -> 0 | U4: =IF(AND(GateFacts[[#This Row],[الحالة]]="مكتمل",COUNTIFS(GateFacts[رقم المشروع],GateFacts[[#This Row],[رقم المشروع]],GateFacts[رقم البوابة],"<"&GateFacts[[#This Row],[رقم البوابة]],GateFacts[منجزة],0)>0),1,0) -> 0 | V4: =SUBTOTAL(103,GateFacts[[#This Row],[م]])*OR(SelRegion="الكل",GateFacts[[#This Row],[المنطقة]]=SelRegion) -> #REF! | W4: {=IF(ISNUMBER(GateFacts[[#This Row],[صف المصدر]]),INDEX(Table15[],GateFacts[[#This Row],[صف المصدر]],16),"")} -> الشمالي الغربي
A5: {=ROW()-ROW(GateFacts[#Headers])} -> 4 | B5: =INT((GateFacts[[#This Row],[م]]-1)/8)+1 -> 1 | C5: =MOD(GateFacts[[#This Row],[م]]-1,8)+1 -> 4 | D5: {=IFERROR(INDEX(_xlfn.ANCHORARRAY(Settings!$H$2),GateFacts[[#This Row],[رقم المشروع]]),"")} -> 198 | E5: {=INDEX(Table15[],GateFacts[[#This Row],[صف المصدر]],14)&""} -> P858-1 | F5: {=INDEX(Table15[],GateFacts[[#This Row],[صف المصدر]],15)&""} -> تنفيذ شبكات الصرف الصحي في وسط الحناكية | G5: {=INDEX(Table15[],GateFacts[[#This Row],[صف المصدر]],17)&""} -> المدينة المنورة | H5: =N(INDEX(Table15[],GateFacts[[#This Row],[صف المصدر]],18)) -> 88550000 | I5: {=_xlfn.LET(_xlpm.x,TRIM(INDEX(Table15[],GateFacts[[#This Row],[صف المصدر]],22)&""),IF(_xlpm.x="","غير محدد",_xlpm.x))} -> تعزيز التكاليف | J5: ="بوابة "&GateFacts[[#This Row],[رقم البوابة]] -> بوابة 4 | K5: {=INDEX(Settings!$E$2:$E$9,GateFacts[[#This Row],[رقم البوابة]])} -> التصميم | L5: {=_xlfn.LET(_xlpm.c,INDEX(Table15[],GateFacts[[#This Row],[صف المصدر]],9-GateFacts[[#This Row],[رقم البوابة]]),IF(ISBLANK(_xlpm.c),"",_xlpm.c))} -> مكتمل | M5: =_xlfn.LET(_xlpm.v,GateFacts[[#This Row],[القيمة الأصلية]],_xlpm.x,TRIM(_xlpm.v&""),IF(ISNUMBER(_xlpm.v),"تاريخ",IF(OR(_xlpm.x="N/A",_xlpm.x="NA",_xlpm.x="لا ينطبق"),"لا ينطبق",IF(OR(_xlpm.x="مكتمل",_xlpm.x="مكتمل بشروط",_xlpm.x="جاري"),_xlpm.x,IF(_xlpm.x="","فارغ","غير معروف"))))) -> مكتمل | N5: {=_xlfn.LET(_xlpm.r,GateFacts[[#This Row],[صف المصدر]],_xlpm.g,GateFacts[[#This Row],[رقم البوابة]],_xlpm.pd,IF(AND(ISNUMBER(_xlpm.r),_xlpm.g>=6,_xlpm.g<=8),INDEX(Table15[],_xlpm.r,19+_xlpm.g),""),IF(ISNUMBER(_xlpm.pd),_xlpm.pd,""))} | O5: =_xlfn.LET(_xlpm.m,GateFacts[[#This Row],[القيمة الموحدة]],_xlpm.d,GateFacts[[#This Row],[تاريخ البوابة]],IF(OR(_xlpm.m="مكتمل",_xlpm.m="مكتمل بشروط"),Settings!$Q$2,IF(_xlpm.m="لا ينطبق",Settings!$Q$7,IF(AND(ISNUMBER(_xlpm.d),_xlpm.d<=TODAY()),Settings!$Q$3,IF(AND(ISNUMBER(_xlpm.d),_xlpm.d<=TODAY()+AlertDays),Settings!$Q$4,IF(_xlpm.m="جاري","جاري","")))))) -> مكتمل | P5: =IF(ISNUMBER(GateFacts[[#This Row],[تاريخ البوابة]]),GateFacts[[#This Row],[تاريخ البوابة]]-TODAY(),"") | Q5: =IF(ISNUMBER(GateFacts[[#This Row],[تاريخ البوابة]]),TEXT(GateFacts[[#This Row],[تاريخ البوابة]],"yyyy-mm"),"بدون تاريخ") -> بدون تاريخ | R5: =--OR(GateFacts[[#This Row],[الحالة]]="مكتمل",GateFacts[[#This Row],[الحالة]]="لا ينطبق") -> 1 | S5: =_xlfn.LET(_xlpm.m,_xlfn.MINIFS(GateFacts[رقم البوابة],GateFacts[رقم المشروع],GateFacts[[#This Row],[رقم المشروع]],GateFacts[منجزة],0),IF(_xlpm.m=0,9,_xlpm.m)) -> 5 | T5: =--(GateFacts[[#This Row],[رقم البوابة]]=GateFacts[[#This Row],[البوابة الحالية للمشروع]]) -> 0 | U5: =IF(AND(GateFacts[[#This Row],[الحالة]]="مكتمل",COUNTIFS(GateFacts[رقم المشروع],GateFacts[[#This Row],[رقم المشروع]],GateFacts[رقم البوابة],"<"&GateFacts[[#This Row],[رقم البوابة]],GateFacts[منجزة],0)>0),1,0) -> 0 | V5: =SUBTOTAL(103,GateFacts[[#This Row],[م]])*OR(SelRegion="الكل",GateFacts[[#This Row],[المنطقة]]=SelRegion) -> #REF! | W5: {=IF(ISNUMBER(GateFacts[[#This Row],[صف المصدر]]),INDEX(Table15[],GateFacts[[#This Row],[صف المصدر]],16),"")} -> الشمالي الغربي
